<?xml version="1.0" encoding="utf-8"?>
<robot xmlns:xacro="http://ros.org/wiki/xacro">
    <xacro:include filename="$(find picknik_accessories)/descriptions/brackets/ur_realsense_camera_adapter/picknik_ur_camera_adapter.urdf.xacro"/>
    <xacro:include filename="$(find picknik_accessories)/descriptions/sensors/realsense_d415.urdf.xacro"/>
    <xacro:include filename="$(find robotiq_description)/urdf/ur_to_robotiq_adapter.urdf.xacro" />
    <xacro:include filename="$(find robotiq_description)/urdf/robotiq_2f_85_macro.urdf.xacro" />
    <xacro:include filename="$(find picknik_accessories)/descriptions/brackets/mtc_ur_tool_changer/mtc_ur_tool_changer.urdf.xacro"/>

    <xacro:macro name="picknik_ur_attachments" params="prefix:='' parent child has_tool_changer">
        <!-- prefix property -->
        <xacro:property name="prefix_" value='${prefix + "_" if prefix else ""}' />
        <!-- parameters -->
        <xacro:arg name="simulation" default=""/>

        <!-- tool changer-->
        <xacro:if value="$(arg has_tool_changer)">
            <xacro:mtc_ur_tool_changer prefix="${prefix_}" parent="${parent}" child="${prefix_}tool_changer_tool0" rotation="0"/>
            <xacro:property name="ur_realsense_camera_adapter_parent" value="${prefix_}tool_changer_tool0" />
        </xacro:if>
        <xacro:unless value="$(arg has_tool_changer)">
            <xacro:property name="ur_realsense_camera_adapter_parent" value="${parent}" />
        </xacro:unless>

        <!-- wrist camera adapter and camera-->
        <xacro:ur_realsense_camera_adapter prefix="${prefix_}" parent="${ur_realsense_camera_adapter_parent}" child_tool="${prefix_}realsense_camera_adapter_tool0" child_camera="${prefix_}d415_mount_link" rotation="0"/>

        <xacro:property name="simulation" default="$(arg simulation)"/>
        <xacro:realsense_d415 parent="${prefix_}d415_mount_link" name="${prefix_}wrist_mounted_camera" use_mesh="${not simulation == 'gazebo'}">
            <origin xyz="0 0 0" rpy="0 0 0"/>
        </xacro:realsense_d415>

        <!-- gripper and UR adapter-->
        <xacro:ur_to_robotiq prefix="${prefix_}" parent="${prefix_}realsense_camera_adapter_tool0" child="${prefix_}gripper_mount_link" rotation="0"/>

        <xacro:if value="${simulation == 'gazebo'}">
            <xacro:property name="use_fake_hardware" default="false"/>
            <xacro:property name="sim_ignition" default="true"/>
        </xacro:if>
        <xacro:if value="${not simulation == 'gazebo'}">
            <xacro:property name="use_fake_hardware" default="$(arg use_fake_hardware)"/>
            <xacro:property name="sim_ignition" default="false"/>
        </xacro:if>

    <!-- Add robotiq 2f 85 gripper model -->
    <link name="robotiq_85_base_link">
      <visual>
        <geometry>
          <mesh filename="package://robotiq_description/meshes/visual/2f_85/robotiq_base.dae"/>
        </geometry>
      </visual>
      <collision>
        <geometry>
          <mesh filename="package://robotiq_description/meshes/collision/2f_85/robotiq_base.stl"/>
        </geometry>
      </collision>
      <inertial>
        <origin rpy="0 0 0" xyz="0.0 2.274e-05 0.03232288"/>
        <mass value="6.6320197e-01"/>
        <inertia ixx="5.1617816e-04" ixy="2.936e-8" ixz="0.0" iyy="5.8802208e-04" iyz="-3.2296e-7" izz="3.9462776e-04"/>
      </inertial>
    </link>
    <link name="robotiq_85_left_knuckle_link">
      <visual>
        <geometry>
          <mesh filename="package://robotiq_description/meshes/visual/2f_85/left_knuckle.dae"/>
        </geometry>
      </visual>
      <collision>
        <geometry>
          <mesh filename="package://robotiq_description/meshes/collision/2f_85/left_knuckle.stl"/>
        </geometry>
      </collision>
      <inertial>
        <origin rpy="0 0 0" xyz="0.01213197 0.0002 -0.00058647"/>
        <mass value="1.384773208e-02"/>
        <inertia ixx="3.5232e-7" ixy="0.0" ixz="1.1744e-7" iyy="2.31944e-6" iyz="0" izz="2.23136e-6"/>
      </inertial>
    </link>
    <link name="robotiq_85_right_knuckle_link">
      <visual>
        <geometry>
          <mesh filename="package://robotiq_description/meshes/visual/2f_85/right_knuckle.dae"/>
        </geometry>
      </visual>
      <collision>
        <geometry>
          <mesh filename="package://robotiq_description/meshes/collision/2f_85/right_knuckle.stl"/>
        </geometry>
      </collision>
      <inertial>
        <origin rpy="0 0 0" xyz="-0.01213197 0.0002 -0.00058647"/>
        <mass value="1.384773208e-02"/>
        <inertia ixx="3.5232e-7" ixy="0.0" ixz="-1.1744e-7" iyy="2.31944e-6" iyz="0.0" izz="2.23136e-6"/>
      </inertial>
    </link>
    <link name="robotiq_85_left_finger_link">
      <visual>
        <geometry>
          <mesh filename="package://robotiq_description/meshes/visual/2f_85/left_finger.dae"/>
        </geometry>
      </visual>
      <collision>
        <geometry>
          <mesh filename="package://robotiq_description/meshes/collision/2f_85/left_finger.stl"/>
        </geometry>
      </collision>
      <inertial>
        <origin rpy="0 0 0" xyz="0.00346899 -0.00079447 0.01867121"/>
        <mass value="4.260376752e-02"/>
        <inertia ixx="1.385792000000000e-05" ixy="0.0" ixz="-2.17264e-06" iyy="1.183208e-05" iyz="0.0" izz="5.19672e-06"/>
      </inertial>
    </link>
    <link name="robotiq_85_right_finger_link">
      <visual>
        <geometry>
          <mesh filename="package://robotiq_description/meshes/visual/2f_85/right_finger.dae"/>
        </geometry>
      </visual>
      <collision>
        <geometry>
          <mesh filename="package://robotiq_description/meshes/collision/2f_85/right_finger.stl"/>
        </geometry>
      </collision>
      <inertial>
        <origin rpy="0 0 0" xyz="-0.00346899 -5.53e-06 0.01867121"/>
        <mass value="4.260376752000000e-02"/>
        <inertia ixx="1.385792e-05" ixy="0.0" ixz="2.17264e-06" iyy="1.183208e-05" iyz="0.0" izz="5.19672e-06"/>
      </inertial>
    </link>
    <link name="robotiq_85_left_inner_knuckle_link">
      <visual>
        <geometry>
          <mesh filename="package://robotiq_description/meshes/visual/2f_85/left_inner_knuckle.dae"/>
        </geometry>
      </visual>
      <collision>
        <geometry>
          <mesh filename="package://robotiq_description/meshes/collision/2f_85/left_inner_knuckle.stl"/>
        </geometry>
      </collision>
      <inertial>
        <origin rpy="0 0 0" xyz="0.01897699 0.00015001 0.02247101"/>
        <mass value="2.969376448e-02"/>
        <inertia ixx="9.57136e-06" ixy="0.0" ixz="-3.93424e-06" iyy="8.69056e-06" iyz="0.0" izz="8.19144e-06"/>
      </inertial>
    </link>
    <link name="robotiq_85_right_inner_knuckle_link">
      <visual>
        <geometry>
          <mesh filename="package://robotiq_description/meshes/visual/2f_85/right_inner_knuckle.dae"/>
        </geometry>
      </visual>
      <collision>
        <geometry>
          <mesh filename="package://robotiq_description/meshes/collision/2f_85/right_inner_knuckle.stl"/>
        </geometry>
      </collision>
      <inertial>
        <origin rpy="0 0 0" xyz="-0.01926824 5.001e-05 0.02222178"/>
        <mass value="2.969376448e-02"/>
        <inertia ixx="9.42456e-06" ixy="0.0" ixz="3.9636e-06" iyy="8.69056e-06" iyz="0.0" izz="8.33824e-06"/>
      </inertial>
    </link>
    <link name="robotiq_85_left_finger_tip_link">
      <visual>
        <geometry>
          <mesh filename="package://robotiq_description/meshes/visual/2f_85/left_finger_tip.dae"/>
        </geometry>
      </visual>
      <collision>
        <geometry>
          <mesh filename="package://robotiq_description/meshes/collision/2f_85/left_finger_tip.stl"/>
        </geometry>
        <surface>
          <friction>
            <ode>
              <mu1>100000.0</mu1>
              <mu2>100000.0</mu2>
            </ode>
          </friction>
          <contact>
            <ode>
              <kp>1e+5</kp>
              <kd>1</kd>
              <soft_cfm>0</soft_cfm>
              <soft_erp>0.2</soft_erp>
              <minDepth>0.002</minDepth>
              <maxVel>0</maxVel>
            </ode>
          </contact>
        </surface>
      </collision>
      <inertial>
        <origin rpy="0 0 0" xyz="-0.01456706 -0.0008 0.01649701"/>
        <mass value="4.268588744e-02"/>
        <inertia ixx="1.048152e-05" ixy="0.0" ixz="3.5232e-6" iyy="1.197888e-05" iyz="0.0" izz="4.22784e-06"/>
      </inertial>
    </link>
    <link name="robotiq_85_right_finger_tip_link">
      <visual>
        <geometry>
          <mesh filename="package://robotiq_description/meshes/visual/2f_85/right_finger_tip.dae"/>
        </geometry>
      </visual>
      <collision>
        <geometry>
          <mesh filename="package://robotiq_description/meshes/collision/2f_85/right_finger_tip.stl"/>
        </geometry>
        <surface>
          <friction>
            <ode>
              <mu1>100000.0</mu1>
              <mu2>100000.0</mu2>
            </ode>
          </friction>
          <contact>
            <ode>
              <kp>1e+5</kp>
              <kd>1</kd>
              <soft_cfm>0</soft_cfm>
              <soft_erp>0.2</soft_erp>
              <minDepth>0.002</minDepth>
              <maxVel>0</maxVel>
            </ode>
          </contact>
        </surface>
      </collision>
      <inertial>
        <origin rpy="0 0 0" xyz="0.01456706 5e-05 0.01649701"/>
        <mass value="4.268588744e-02"/>
        <inertia ixx="1.048152e-05" ixy="0.0" ixz="-3.5232e-06" iyy="1.197888e-05" iyz="0.0" izz="4.22784e-06"/>
      </inertial>
    </link>
    <joint name="robotiq_85_base_joint" type="fixed">
      <parent link="${prefix_}gripper_mount_link"/>
      <child link="robotiq_85_base_link"/>
      <origin rpy="0 0 0" xyz="0 0 0"/>
    </joint>
    <joint name="robotiq_85_left_knuckle_joint" type="revolute">
      <parent link="robotiq_85_base_link"/>
      <child link="robotiq_85_left_knuckle_link"/>
      <axis xyz="0 -1 0"/>
      <origin rpy="0 0 0" xyz="0.03060114 0.0 0.05490452"/>
      <limit effort="50" lower="0.0" upper="0.8" velocity="0.5"/>
    </joint>
    <joint name="robotiq_85_right_knuckle_joint" type="revolute">
      <parent link="robotiq_85_base_link"/>
      <child link="robotiq_85_right_knuckle_link"/>
      <axis xyz="0 1 0"/>
      <origin rpy="0 0 0" xyz="-0.03060114 0.0 0.05490452"/>
      <limit effort="50" lower="0.0" upper="0.8" velocity="0.5"/>
      <mimic joint="robotiq_85_left_knuckle_joint" multiplier="1"/>
    </joint>
    <joint name="robotiq_85_left_finger_joint" type="fixed">
      <parent link="robotiq_85_left_knuckle_link"/>
      <child link="robotiq_85_left_finger_link"/>
      <axis xyz="0 -1 0"/>
      <origin rpy="0 0 0" xyz="0.03152616 0.0 -0.00376347"/>
    </joint>
    <joint name="robotiq_85_right_finger_joint" type="fixed">
      <parent link="robotiq_85_right_knuckle_link"/>
      <child link="robotiq_85_right_finger_link"/>
      <axis xyz="0 1 0"/>
      <origin rpy="0 0 0" xyz="-0.03152616 0.0 -0.00376347"/>
    </joint>
    <joint name="robotiq_85_left_inner_knuckle_joint" type="continuous">
      <parent link="robotiq_85_base_link"/>
      <child link="robotiq_85_left_inner_knuckle_link"/>
      <axis xyz="0 -1 0"/>
      <origin rpy="0 0 0" xyz="0.0127 0.0 0.06142"/>
      <mimic joint="robotiq_85_left_knuckle_joint" multiplier="1"/>
    </joint>
    <joint name="robotiq_85_right_inner_knuckle_joint" type="continuous">
      <parent link="robotiq_85_base_link"/>
      <child link="robotiq_85_right_inner_knuckle_link"/>
      <axis xyz="0 1 0"/>
      <origin rpy="0 0 0" xyz="-0.0127 0.0 0.06142"/>
      <mimic joint="robotiq_85_left_knuckle_joint" multiplier="1"/>
    </joint>
    <joint name="robotiq_85_left_finger_tip_joint" type="continuous">
      <parent link="robotiq_85_left_finger_link"/>
      <child link="robotiq_85_left_finger_tip_link"/>
      <axis xyz="0 -1 0"/>
      <origin rpy="0 0 0" xyz="0.00563134 0.0 0.04718515"/>
      <mimic joint="robotiq_85_left_knuckle_joint" multiplier="-1"/>
    </joint>
    <joint name="robotiq_85_right_finger_tip_joint" type="continuous">
      <parent link="robotiq_85_right_finger_link"/>
      <child link="robotiq_85_right_finger_tip_link"/>
      <axis xyz="0 1 0"/>
      <origin rpy="0 0 0" xyz="-0.00563134 0.0 0.04718515"/>
      <mimic joint="robotiq_85_left_knuckle_joint" multiplier="-1"/>
    </joint>

        <!-- This link aligns the axes of the grasp frame to our required convention for motion planning tasks. -->
        <link name="${child}"/>
        <joint name="${child}_joint" type="fixed">
            <parent link="${prefix_}robotiq_85_base_link"/>
            <child link="${child}"/>
            <origin xyz="0.0 0.0 0.134" rpy="0.0 0.0 ${pi}"/>
        </joint>
    </xacro:macro>
</robot>
